Workbook

Sheet PORTADA
B2: FORMATOS ADMINISTRATIVOS | E2: VERSIÓN 2.0 · MÉXICO
B4: PRESUPUESTO COMERCIAL
B6: Formato administrativo profesional · editable · listo para imprimir
C9: FÓRMULAS AUTOMÁTICAS | D9: LISTAS DESPLEGABLES | E9: HOJAS PROTEGIDAS | F9: LISTO PARA IMPRIMIR
B15: ¿QUÉ INCLUYE ESTE ARCHIVO?
B16: ▸ | C16: PRESUPUESTO
B17: ▸ | C17: ALCANCE
B18: ▸ | C18: RESUMEN | D18: Tablero con indicadores y gráficas que se actualizan automáticamente con tus datos.
B19: ▸ | C19: AYUDA | D19: Preguntas frecuentes, glosario y lista de verificación para cerrar tu periodo.
B21: FICHA TÉCNICA
C22: Capacidad | D22: 3 opciones · 3 fases · hasta 17 conceptos
C23: Compatibilidad | D23: Excel 2016, 2019, 2021 y Microsoft 365 (Windows y Mac)
C24: Idioma y moneda | D24: Español (México) · Pesos mexicanos (MXN) · IVA 16%
C25: Protección | D25: Hojas protegidas sin contraseña (Revisar > Desproteger hoja)
C26: Fuente | D26: Arial (disponible en Windows, Mac y Google Sheets)
B28: CÓMO USARLO
B29: 1 | C29: Captura cliente, proyecto, fecha y elige la OPCIÓN RECOMENDADA (celda B7): se resalta en dorado en todo el libro.
B30: 2 | C30: En cada fase escribe clave, concepto, tipo (directo/indirecto), precio unitario y la cantidad que incluye cada opción; cantidad 0 = no incluye.
B31: 3 | C31: Captura descuento (%) y duración en semanas por opción; el IVA, el total y la inversión por semana se calculan solos.
B32: 4 | C32: Ajusta el cronograma de pagos; la celda de verificación confirma que suma 100%.
B33: 5 | C33: Redacta alcance, entregables, beneficios, exclusiones y condiciones en la hoja ALCANCE y revisa el ANÁLISIS DE VALOR antes de enviar.
B34: 6 | C34: Personaliza: inserta tu logotipo en el recuadro punteado de la esquina superior derecha (Insertar > Imágenes) y captura los datos de tu empresa en las celdas de captura.
B36: RECOMENDACIONES DE USO
B37: ✓ | C37: Presenta siempre tres opciones: la del medio suele ser la recomendada y ancla la decisión del cliente.
B38: ✓ | C38: Cada opción debe diferenciarse por alcance, no solo por precio: más entregables, más control, más acompañamiento.
B39: ✓ | C39: Marca la opción recomendada en la celda B7 del PRESUPUESTO: se resalta sola en dorado.
B40: ✓ | C40: Separa costos directos (lo que el cliente ve) de indirectos (gestión, coordinación) para explicar el precio.
B41: ✓ | C41: El cronograma de pagos debe sumar 100%; la celda de verificación te avisa.
B42: ✓ | C42: Envía el presupuesto en PDF junto con la propuesta comercial (Word) y confirma la vigencia.
B44: LEYENDA DE COLORES
C45: CELDA DE CAPTURA: escribe aquí.
C46: CÁLCULO AUTOMÁTICO: no la modifiques.
C47: ENCABEZADOS Y TÍTULOS.
C48: * CAMPO OBLIGATORIO: complétalo antes de imprimir o enviar.
B50: Formatos administrativos · Para uso interno de tu empresa

Sheet PRESUPUESTO
A1: PRESUPUESTO COMERCIAL · TRES OPCIONES | I1: INSERTE SU LOGO (clic derecho > Insertar imagen)
A2: Esencial, profesional y estratégico: inversión, alcance y condiciones
A4: CLIENTE * | E4: FOLIO *
A5: PROYECTO | E5: FECHA *
A6: ELABORÓ | E6: VIGENCIA (DÍAS) | F6: 15
A7: OPCIÓN RECOMENDADA | B7: PROFESIONAL | E7: IVA | F7: 0.16
A9: Marca con * lo obligatorio. Captura cantidad 0 en las opciones que NO incluyen un concepto. | H9: =IF($B$7=H$11,"★ RECOMENDADA","") | I9: =IF($B$7=I$11,"★ RECOMENDADA","") | J9: =IF($B$7=J$11,"★ RECOMENDADA","")
H10: PARA EMPEZAR | I10: EL MÁS ELEGIDO | J10: MÁXIMO CONTROL
A11: CLAVE | B11: CONCEPTO | C11: TIPO | D11: PRECIO UNITARIO | E11: CANT. ESENCIAL | F11: CANT. PROFESIONAL | G11: CANT. ESTRATÉGICO | H11: ESENCIAL | I11: PROFESIONAL | J11: ESTRATÉGICO
A12: FASE 1 · ORDENAR (DIAGNÓSTICO)
H13: =IF(OR($D13="",E13=""),"",$D13*E13) | I13: =IF(OR($D13="",F13=""),"",$D13*F13) | J13: =IF(OR($D13="",G13=""),"",$D13*G13)
H14: =IF(OR($D14="",E14=""),"",$D14*E14) | I14: =IF(OR($D14="",F14=""),"",$D14*F14) | J14: =IF(OR($D14="",G14=""),"",$D14*G14)
H15: =IF(OR($D15="",E15=""),"",$D15*E15) | I15: =IF(OR($D15="",F15=""),"",$D15*F15) | J15: =IF(OR($D15="",G15=""),"",$D15*G15)
H16: =IF(OR($D16="",E16=""),"",$D16*E16) | I16: =IF(OR($D16="",F16=""),"",$D16*F16) | J16: =IF(OR($D16="",G16=""),"",$D16*G16)
H17: =IF(OR($D17="",E17=""),"",$D17*E17) | I17: =IF(OR($D17="",F17=""),"",$D17*F17) | J17: =IF(OR($D17="",G17=""),"",$D17*G17)
H18: =IF(OR($D18="",E18=""),"",$D18*E18) | I18: =IF(OR($D18="",F18=""),"",$D18*F18) | J18: =IF(OR($D18="",G18=""),"",$D18*G18)
B19: SUBTOTAL FASE 1 | H19: =SUM(H13:H18) | I19: =SUM(I13:I18) | J19: =SUM(J13:J18)
A20: FASE 2 · PLANEAR E IMPLEMENTAR
H21: =IF(OR($D21="",E21=""),"",$D21*E21) | I21: =IF(OR($D21="",F21=""),"",$D21*F21) | J21: =IF(OR($D21="",G21=""),"",$D21*G21)
H22: =IF(OR($D22="",E22=""),"",$D22*E22) | I22: =IF(OR($D22="",F22=""),"",$D22*F22) | J22: =IF(OR($D22="",G22=""),"",$D22*G22)
H23: =IF(OR($D23="",E23=""),"",$D23*E23) | I23: =IF(OR($D23="",F23=""),"",$D23*F23) | J23: =IF(OR($D23="",G23=""),"",$D23*G23)
H24: =IF(OR($D24="",E24=""),"",$D24*E24) | I24: =IF(OR($D24="",F24=""),"",$D24*F24) | J24: =IF(OR($D24="",G24=""),"",$D24*G24)
H25: =IF(OR($D25="",E25=""),"",$D25*E25) | I25: =IF(OR($D25="",F25=""),"",$D25*F25) | J25: =IF(OR($D25="",G25=""),"",$D25*G25)
H26: =IF(OR($D26="",E26=""),"",$D26*E26) | I26: =IF(OR($D26="",F26=""),"",$D26*F26) | J26: =IF(OR($D26="",G26=""),"",$D26*G26)
B27: SUBTOTAL FASE 2 | H27: =SUM(H21:H26) | I27: =SUM(I21:I26) | J27: =SUM(J21:J26)
A28: FASE 3 · EJECUTAR Y CERRAR
H29: =IF(OR($D29="",E29=""),"",$D29*E29) | I29: =IF(OR($D29="",F29=""),"",$D29*F29) | J29: =IF(OR($D29="",G29=""),"",$D29*G29)
H30: =IF(OR($D30="",E30=""),"",$D30*E30) | I30: =IF(OR($D30="",F30=""),"",$D30*F30) | J30: =IF(OR($D30="",G30=""),"",$D30*G30)
H31: =IF(OR($D31="",E31=""),"",$D31*E31) | I31: =IF(OR($D31="",F31=""),"",$D31*F31) | J31: =IF(OR($D31="",G31=""),"",$D31*G31)
H32: =IF(OR($D32="",E32=""),"",$D32*E32) | I32: =IF(OR($D32="",F32=""),"",$D32*F32) | J32: =IF(OR($D32="",G32=""),"",$D32*G32)
H33: =IF(OR($D33="",E33=""),"",$D33*E33) | I33: =IF(OR($D33="",F33=""),"",$D33*F33) | J33: =IF(OR($D33="",G33=""),"",$D33*G33)
B34: SUBTOTAL FASE 3 | H34: =SUM(H29:H33) | I34: =SUM(I29:I33) | J34: =SUM(J29:J33)
A36: COSTOS DIRECTOS | H36: =SUMIF($C$12:$C$34,"DIRECTO",H12:H34) | I36: =SUMIF($C$12:$C$34,"DIRECTO",I12:I34) | J36: =SUMIF($C$12:$C$34,"DIRECTO",J12:J34)
A37: COSTOS INDIRECTOS | H37: =SUMIF($C$12:$C$34,"INDIRECTO",H12:H34) | I37: =SUMIF($C$12:$C$34,"INDIRECTO",I12:I34) | J37: =SUMIF($C$12:$C$34,"INDIRECTO",J12:J34)
A38: SUBTOTAL | H38: =H36+H37 | I38: =I36+I37 | J38: =J36+J37
A39: DESCUENTO (%) | H39: 0 | I39: 0 | J39: 0
A40: DESCUENTO ($) | H40: =H38*H39 | I40: =I38*I39 | J40: =J38*J39
A41: SUBTOTAL NETO | H41: =H38-H40 | I41: =I38-I40 | J41: =J38-J40
A42: IVA | H42: =H41*$F$7 | I42: =I41*$F$7 | J42: =J41*$F$7
A43: TOTAL DE LA INVERSIÓN | H43: =H41+H42 | I43: =I41+I42 | J43: =J41+J42
...

Sheet ALCANCE
A1: ALCANCE Y CONDICIONES POR OPCIÓN | D1: INSERTE SU LOGO (clic derecho > Insertar imagen)
A2: Lo que incluye cada opción, qué se entrega y qué queda fuera
B3: =IF(PRESUPUESTO!$B$7=B4,"★ RECOMENDADA","") | C3: =IF(PRESUPUESTO!$B$7=C4,"★ RECOMENDADA","") | D3: =IF(PRESUPUESTO!$B$7=D4,"★ RECOMENDADA","")
A4: CONCEPTO | B4: ESENCIAL | C4: PROFESIONAL | D4: ESTRATÉGICO
A5: ALCANCE | B5: [Diagnóstico y plan de trabajo] | C5: [Diagnóstico, implementación de controles y tablero] | D5: [Implementación integral, capacitación y soporte]
A6: ENTREGABLES | B6: [Informe de diagnóstico · Libro de control] | C6: [Informe · Libro de control · Tablero · Reporte semanal] | D6: [Todo lo anterior · Procedimientos · Plan a 90 días]
A7: TIEMPO DE ENTREGA | B7: [4 semanas] | C7: [6 semanas] | D7: [8 semanas]
A8: BENEFICIOS CLAVE | B8: [Orden y visibilidad inicial] | C8: [Control semanal y decisiones con información] | D8: [Operación estandarizada y cierre con evidencia]
A9: EXCLUSIONES | B9: [Capacitación · Soporte posterior] | C9: [Soporte posterior al cierre] | D9: [Trámites ante autoridades]
A10: CONDICIONES COMERCIALES | B10: [Pago 40/30/30 · Vigencia 15 días] | C10: [Pago 40/30/30 · Vigencia 15 días] | D10: [Pago 40/30/30 · Vigencia 15 días]

Sheet RESUMEN
A1: ANÁLISIS DE VALOR | H1: INSERTE SU LOGO (clic derecho > Insertar imagen)
A2: Comparativo de inversión por opción y por fase
B4: OPCIÓN RECOMENDADA | D4: INVERSIÓN RECOMENDADA | F4: BRECHA ENTRE OPCIONES | H4: INVERSIÓN POR SEMANA (REC.)
B5: =PRESUPUESTO!B7 | D5: =IFERROR(INDEX(PRESUPUESTO!H43:J43,MATCH(PRESUPUESTO!B7,PRESUPUESTO!H11:J11,0)),0) | F5: =PRESUPUESTO!J43-PRESUPUESTO!H43 | H5: =IFERROR(INDEX(PRESUPUESTO!H45:J45,MATCH(PRESUPUESTO!B7,PRESUPUESTO!H11:J11,0)),0)
B7: =IF(D5=0,"Captura conceptos y precios en la hoja PRESUPUESTO para ver el análisis.","La opción "&B5&" requiere $"&TEXT(D5,"#,##0")&" (IVA incluido). Pasar de la esencial a la estratégica agrega $"&TEXT(F5,"#,##0")&" de inversión a cambio de mayor alcance y control.")
B25: OPCIÓN | C25: FASE 1 | D25: FASE 2 | E25: FASE 3 | F25: TOTAL SIN IVA
B26: ESENCIAL | C26: =PRESUPUESTO!H19 | D26: =PRESUPUESTO!H27 | E26: =PRESUPUESTO!H34 | F26: =PRESUPUESTO!H41
B27: PROFESIONAL | C27: =PRESUPUESTO!I19 | D27: =PRESUPUESTO!I27 | E27: =PRESUPUESTO!I34 | F27: =PRESUPUESTO!I41
B28: ESTRATÉGICO | C28: =PRESUPUESTO!J19 | D28: =PRESUPUESTO!J27 | E28: =PRESUPUESTO!J34 | F28: =PRESUPUESTO!J41

Sheet AYUDA
B1: AYUDA Y PREGUNTAS FRECUENTES
B2: PRESUPUESTO COMERCIAL
B5: PREGUNTAS FRECUENTES
C6: ¿Cómo cambio los conceptos y precios? | D6: Escribe en las celdas de captura de cada fase: clave, concepto, tipo, precio unitario y la cantidad que incluye cada opción (0 = no incluye).
C7: ¿Cómo funciona el descuento? | D7: Captura un porcentaje por opción; el IVA se calcula sobre el subtotal neto con el % de IVA de la celda F7.
C8: ¿Qué es el análisis de valor? | D8: Divide la inversión total entre las semanas de duración para comparar el costo semanal de cada opción.
C9: ¿Por qué no puedo escribir en algunas celdas? | D9: La hoja está protegida para que no se borren fórmulas por accidente. Solo se editan las celdas de captura (color crema). Si necesitas modificar algo más: pestaña Revisar > Desproteger hoja (no tiene contraseña).
C10: ¿Cómo agrego mi logotipo? | D10: Haz clic en el recuadro punteado de la esquina superior derecha del formato y usa Insertar > Imágenes. Ajusta el tamaño sin salirte del recuadro.
C11: ¿Cómo lo imprimo o lo convierto a PDF? | D11: Archivo > Imprimir (ya está ajustado a una hoja de ancho). Para PDF elige 'Microsoft Print to PDF' o Archivo > Exportar > PDF.
C12: ¿Con qué versiones de Excel funciona? | D12: Excel 2016, 2019, 2021 y Microsoft 365 (Windows y Mac). Funciona en LibreOffice y Google Sheets, aunque algunas gráficas y formatos pueden verse distintos.
C13: ¿Puedo cambiar la letra? | D13: El diseño usa la fuente Arial, disponible en Windows, Mac y Google Sheets. Si necesitas otra, selecciona todo (Ctrl+E) y cambia la fuente; no afecta el funcionamiento.
C14: ¿Puedo usarlo en varias empresas o por varios años? | D14: Sí. Guarda una copia del archivo por empresa o por periodo (Archivo > Guardar como) y deja el original en blanco como plantilla maestra.
B16: GLOSARIO
C17: COSTO DIRECTO | D17: Trabajo o producto que el cliente recibe de forma visible.
C18: COSTO INDIRECTO | D18: Gestión, coordinación y administración del proyecto.
C19: OPCIÓN RECOMENDADA | D19: Paquete que mejor equilibra alcance e inversión para el cliente.
C20: VIGENCIA | D20: Días durante los cuales se respetan los precios.
C21: ANTICIPO | D21: Pago inicial que activa el calendario del proyecto.
B23: LISTA DE VERIFICACIÓN (marca ☑ al completar)
B24: ☐ | C24: Datos del cliente y proyecto completos
B25: ☐ | C25: Conceptos, precios y cantidades por opción
B26: ☐ | C26: Opción recomendada seleccionada
B27: ☐ | C27: Cronograma de pagos suma 100%
B28: ☐ | C28: Alcance, entregables y exclusiones redactados (hoja ALCANCE)
B29: ☐ | C29: PDF enviado con la propuesta
